Workbook

Sheet Pricing Workbook
B1: Inputs | I1: Inspection Work | J1: Inputs | K1: Price
A2: Total Squares | B2: 58 | I2: # of Additional Layers | J2: 1 | K2: =+Backend!D159/(1-B19) -> 786.44068
A3: Non-Walk & 2nd Story Sq(s) | B3: 0 | I3: Pipeboots | J3: 2 | K3: =+Backend!D160/(1-B19) -> 52.20339
A4: Flat Roof Sq(s) | B4: 0 | F4: Labor SQ | I4: Roof Vents | J4: 2 | K4: =+Backend!D162/(1-B19) -> 130.50847
A5: Ridge ln ft | B5: 0 | F5: =B5/75 -> 0 | I5: Electrical Boot | J5: 0 | K5: =+Backend!D161/(1-B19) -> 0
A6: Hip ln ft | B6: 0 | F6: =B6/75 -> 0 | I6: Decking (per Sheet) | J6: 10 | K6: =Backend!D165/(1-B19) -> 906.77966
A7: Valley ln ft | B7: 0 | I7: Structural Framing ln ft | J7: 0 | K7: =+Backend!D166/(1-B19) -> 0
A8: Rake ln ft | B8: 0 | F8: =B8/300 -> 0 | I8: Wall Flashing ln ft | J8: 35 | K8: =Backend!D167/(1-B19) -> 289.83051
A9: Eave ln ft | B9: 0 | F9: =B9/300 -> 0 | I9: Chimney Flashing | J9: 0 | K9: =+Backend!D163/(1-B19) -> 0
A10: Labor Squares | I10: Skylight Flashing | J10: 0 | K10: =+Backend!D164/(1-B19) -> 0
I11: Fasia per ln ft | J11: 0 | K11: =+Backend!D168/(1-B19) -> 0
A12: Financing | I12: Soffit per ln ft | J12: 0 | K12: =+Backend!D169/(1-B19) -> 0
A13: Dealer Fee % | B13: 0 | I13: Smart Vents per ln ft | J13: 0 | K13: =+Backend!D170/(1-B19) -> 0
A14: Interest Rate | B14: 0.1299 | I14: --------------------------------- | J14: Total | K14: =SUM(K2:K13) -> 2165.7627
A15: Months of Loan | B15: 180 | I15: Gutters per ln ft | J15: 0 | K15: =+Backend!D174/(1-B19) -> 0
A16: Down payment | B16: 0 | I16: # of Downspouts | J16: 0 | K16: =+Backend!D176/(1-B19) -> 0
I17: gutter guards per ln ft | J17: 0 | K17: =+Backend!D175/(1-B19) -> 0
A18: Extra Factors | J18: Total | K18: =SUM(K15:K17) -> 0
A19: Margin (must have % sign) | B19: 0.41
B22: Shingles | J22: Metal
A23: 30 and 5 | B23: Cash Price | F23: with DF and DP | G23: Monthly | I23: Rib panel 26 ga | J23: Cash Price | K23: with DF and DP | L23: Monthly
A24: Marketing Discount | B24: =+Backend!F59 -> 26645.508 | F24: =(B24*(1+B13))-B16 -> 26645.508 | G24: =PMT(B14/12,B15,F24)*-1 -> 336.9549 | I24: Marketing Discount | J24: =+Backend!F62 -> 40584.068 | K24: =(J24*(1+B13))-B16 -> 40584.068 | L24: =PMT(B14/12,B15,K24)*-1 -> 513.21973
A25: Online Coupon | B25: =B24+1000 -> 27645.508 | F25: =(B25*(1+B13))-B16 -> 27645.508 | G25: =PMT(B14/12,B15,F25)*-1 -> 349.60074 | I25: Online Coupon | J25: =J24+1000 -> 41584.068 | K25: =(J25*(1+B13))-B16 -> 41584.068 | L25: =PMT(B14/12,B15,K25)*-1 -> 525.86557
A26: 30 Day Price | B26: =B25*1.2 -> 33174.61 | F26: =(B26*(1+B13))-B16 -> 33174.61 | G26: =PMT(B14/12,B15,F26)*-1 -> 419.52089 | I26: 30 Day Price | J26: =J25*1.2 -> 49900.881 | K26: =(J26*(1+B13))-B16 -> 49900.881 | L26: =PMT(B14/12,B15,K26)*-1 -> 631.03868
A28: 30 and 10 | B28: Cash Price | F28: with DF and DP | G28: Monthly | I28: Standing seam 26 ga | J28: Cash Price | K28: with DF and DP | L28: Monthly
A29: Marketing Discount | B29: =+Backend!F60 -> 26645.508 | F29: =(B29*(1+B13))-B16 -> 26645.508 | G29: =PMT(B14/12,B15,F29)*-1 -> 336.9549 | I29: Marketing Discount | J29: =+Backend!F63 -> 48694.237 | K29: =(J29*(1+B13))-B16 -> 48694.237 | L29: =PMT(B14/12,B15,K29)*-1 -> 615.77965
A30: Online Coupon | B30: =B29+1000 -> 27645.508 | F30: =(B30*(1+B13))-B16 -> 27645.508 | G30: =PMT(B14/12,B15,F30)*-1 -> 349.60074 | I30: Online Coupon | J30: =J29+1000 -> 49694.237 | K30: =(J30*(1+B13))-B16 -> 49694.237 | L30: =PMT(B14/12,B15,K30)*-1 -> 628.42549
A31: 30 Day Price | B31: =B30*1.2 -> 33174.61 | F31: =(B31*(1+B13))-B16 -> 33174.61 | G31: =PMT(B14/12,B15,F31)*-1 -> 419.52089 | I31: 30 Day Price | J31: =J30*1.2 -> 59633.085 | K31: =(J31*(1+B13))-B16 -> 59633.085 | L31: =PMT(B14/12,B15,K31)*-1 -> 754.11059
A33: Class 4 Lifetime | B33: Cash Price | F33: with DF and DP | G33: Monthly | I33: Standing seam 24 ga | J33: Cash Price | K33: with DF and DP | L33: Monthly
A34: Marketing Discount | B34: =+Backend!F61 -> 31702.712 | F34: =(B34*(1+B13))-B16 -> 31702.712 | G34: =PMT(B14/12,B15,F34)*-1 -> 400.9075 | I34: Marketing Discount | J34: =+Backend!F64 -> 50906.102 | K34: =(J34*(1+B13))-B16 -> 50906.102 | L34: =PMT(B14/12,B15,K34)*-1 -> 643.75054
A35: Online Coupon | B35: =B34+1000 -> 32702.712 | F35: =(B35*(1+B13))-B16 -> 32702.712 | G35: =PMT(B14/12,B15,F35)*-1 -> 413.55334 | I35: Online Coupon | J35: =J34+1000 -> 51906.102 | K35: =(J35*(1+B13))-B16 -> 51906.102 | L35: =PMT(B14/12,B15,K35)*-1 -> 656.39638
A36: 30 Day Price | B36: =B35*1.2 -> 39243.254 | F36: =(B36*(1+B13))-B16 -> 39243.254 | G36: =PMT(B14/12,B15,F36)*-1 -> 496.26401 | I36: 30 Day Price | J36: =J35*1.2 -> 62287.322 | K36: =(J36*(1+B13))-B16 -> 62287.322 | L36: =PMT(B14/12,B15,K36)*-1 -> 787.67566
A39: Project Details
A40: Martir
A41: Address
A42: Product
A43: Color
A44: Closing Price
A45: Financed Company or Cash

Sheet Copy of Pricing Workbook
B1: Inputs | F1: Inspection Work | G1: Inputs | H1: Price
A2: Total Squares | B2: 56 | F2: # of Additional Layers | G2: 2 | H2: =+Backend!D159/(1-B19) -> 713.84615
A3: Non-Walk & 2nd Story Sq(s) | B3: 0 | F3: Pipeboots | G3: 3 | H3: =+Backend!D160/(1-B19) -> 47.384615
A4: Flat Roof Sq(s) | B4: 0 | C4: Labor SQ | F4: Roof Vents | G4: 2 | H4: =+Backend!D162/(1-B19) -> 118.46154
A5: Ridge ln ft | B5: 70 | C5: =B5/75 -> 0.93333333 | F5: Electrical Boot | G5: 1 | H5: =+Backend!D161/(1-B19) -> 0
A6: Hip ln ft | B6: 202 | C6: =B6/75 -> 2.6933333 | F6: Decking (per Sheet) | G6: 0 | H6: =Backend!D165/(1-B19) -> 823.07692
A7: Valley ln ft | B7: 106 | F7: Structural Framing ln ft | G7: 0 | H7: =+Backend!D166/(1-B19) -> 0
A8: Rake ln ft | B8: 41 | C8: =B8/300 -> 0.13666667 | F8: Wall Flashing ln ft | G8: 0 | H8: =Backend!D167/(1-B19) -> 263.07692
A9: Eave ln ft | B9: 274 | C9: =B9/300 -> 0.91333333 | F9: Chimney Flashing | G9: 0 | H9: =+Backend!D163/(1-B19) -> 0
A10: Labor Squares | B10: =B2+SUM(C5:C9) -> 60.676667 | F10: Skylight Flashing | G10: 0 | H10: =+Backend!D164/(1-B19) -> 0
F11: Fasia per ln ft | G11: 0 | H11: =+Backend!D168/(1-B19) -> 0
A12: Financing | F12: Soffit per ln ft | G12: 0 | H12: =+Backend!D169/(1-B19) -> 0
A13: Dealer Fee % | B13: 0 | F13: Smart Vents per ln ft | G13: 0 | H13: =+Backend!D170/(1-B19) -> 0
A14: Interest Rate | B14: 0.1299 | F14: --------------------------------- | G14: Total | H14: =SUM(H2:H13) -> 1965.8462
A15: Months of Loan | B15: 120 | F15: Gutters per ln ft | G15: 0 | H15: =+Backend!D174/(1-B19) -> 0
A16: Down payment | B16: 0 | F16: # of Downspouts | G16: 0 | H16: =+Backend!D176/(1-B19) -> 0
F17: gutter guards per ln ft | G17: 0 | H17: =+Backend!D175/(1-B19) -> 0
A18: Extra Factors | G18: Total | H18: =SUM(H15:H17) -> 0
A19: Margin (must have % sign) | B19: 0.35
B22: Shingles | G22: Metal
A23: 30 and 5 | B23: Cash Price | C23: with DF and DP | D23: Monthly | F23: Rib panel 26 ga | G23: Cash Price | H23: with DF and DP | I23: Monthly
A24: Marketing Discount | B24: =+Backend!F59 -> 26645.508 | C24: =(B24*(1+B13))-B16 -> 26645.508 | D24: =PMT(B14/12,B15,C24)*-1 -> 397.68891 | F24: Marketing Discount | G24: =+Backend!F62 -> 40584.068 | H24: =(G24*(1+B13))-B16 -> 40584.068 | I24: =PMT(B14/12,B15,H24)*-1 -> 605.72437
A25: Online Coupon | B25: =B24+1000 -> 27645.508 | C25: =(B25*(1+B13))-B16 -> 27645.508 | D25: =PMT(B14/12,B15,C25)*-1 -> 412.61409 | F25: Online Coupon | G25: =G24+1000 -> 41584.068 | H25: =(G25*(1+B13))-B16 -> 41584.068 | I25: =PMT(B14/12,B15,H25)*-1 -> 620.64954
A26: 30 Day Price | B26: =B25*1.2 -> 33174.61 | C26: =(B26*(1+B13))-B16 -> 33174.61 | D26: =PMT(B14/12,B15,C26)*-1 -> 495.13691 | F26: 30 Day Price | G26: =G25*1.2 -> 49900.881 | H26: =(G26*(1+B13))-B16 -> 49900.881 | I26: =PMT(B14/12,B15,H26)*-1 -> 744.77945
A28: 30 and 10 | B28: Cash Price | C28: with DF and DP | D28: Monthly | F28: Standing seam 26 ga | G28: Cash Price | H28: with DF and DP | I28: Monthly
A29: Marketing Discount | B29: =+Backend!F60 -> 26645.508 | C29: =(B29*(1+B13))-B16 -> 26645.508 | D29: =PMT(B14/12,B15,C29)*-1 -> 397.68891 | F29: Marketing Discount | G29: =+Backend!F63 -> 48694.237 | H29: =(G29*(1+B13))-B16 -> 48694.237 | I29: =PMT(B14/12,B15,H29)*-1 -> 726.77008
A30: Online Coupon | B30: =B29+1000 -> 27645.508 | C30: =(B30*(1+B13))-B16 -> 27645.508 | D30: =PMT(B14/12,B15,C30)*-1 -> 412.61409 | F30: Online Coupon | G30: =G29+1000 -> 49694.237 | H30: =(G30*(1+B13))-B16 -> 49694.237 | I30: =PMT(B14/12,B15,H30)*-1 -> 741.69525
A31: 30 Day Price | B31: =B30*1.2 -> 33174.61 | C31: =(B31*(1+B13))-B16 -> 33174.61 | D31: =PMT(B14/12,B15,C31)*-1 -> 495.13691 | F31: 30 Day Price | G31: =G30*1.2 -> 59633.085 | H31: =(G31*(1+B13))-B16 -> 59633.085 | I31: =PMT(B14/12,B15,H31)*-1 -> 890.03431
A33: Class 4 Lifetime | B33: Cash Price | C33: with DF and DP | D33: Monthly | F33: Standing seam 24 ga | G33: Cash Price | H33: with DF and DP | I33: Monthly
A34: Marketing Discount | B34: =+Backend!F61 -> 31702.712 | C34: =(B34*(1+B13))-B16 -> 31702.712 | D34: =PMT(B14/12,B15,C34)*-1 -> 473.16856 | F34: Marketing Discount | G34: =+Backend!F64 -> 50906.102 | H34: =(G34*(1+B13))-B16 -> 50906.102 | I34: =PMT(B14/12,B15,H34)*-1 -> 759.78254
A35: Online Coupon | B35: =B34+1000 -> 32702.712 | C35: =(B35*(1+B13))-B16 -> 32702.712 | D35: =PMT(B14/12,B15,C35)*-1 -> 488.09374 | F35: Online Coupon | G35: =G34+1000 -> 51906.102 | H35: =(G35*(1+B13))-B16 -> 51906.102 | I35: =PMT(B14/12,B15,H35)*-1 -> 774.70772
A36: 30 Day Price | B36: =B35*1.2 -> 39243.254 | C36: =(B36*(1+B13))-B16 -> 39243.254 | D36: =PMT(B14/12,B15,C36)*-1 -> 585.71249 | F36: 30 Day Price | G36: =G35*1.2 -> 62287.322 | H36: =(G36*(1+B13))-B16 -> 62287.322 | I36: =PMT(B14/12,B15,H36)*-1 -> 929.64926
A39: Project Details
A40: Name
A41: Address
A42: Product
A43: Color
A44: Closing Price
A45: Financed Company or Cash

Sheet Sheet1

Sheet Sheet6

Sheet Sheet5

Sheet Sheet4

Sheet Sheet3

Sheet Sheet2

Sheet Backend
F1: Inspection Items
A2: Walkable Squares | B2: =+'Pricing Workbook'!B2 -> 58 | C2: Ridge | D2: =+'Pricing Workbook'!B5 -> 0 | F2: # of Additional Layers | G2: =+'Pricing Workbook'!J2 -> 1 | H2: Skylight Flashing | I2: =+'Pricing Workbook'!J10 -> 0
A3: Flat Roof Sq(s) | B3: =+'Pricing Workbook'!B4 -> 0 | C3: Hip | D3: =+'Pricing Workbook'!B6 -> 0 | F3: Pipeboots | G3: =+'Pricing Workbook'!J3 -> 2 | H3: Fasia per ln ft | I3: =+'Pricing Workbook'!J11 -> 0
A4: Non-Walkable + 2nd Story Sq | B4: =+'Pricing Workbook'!B3 -> 0 | C4: Eave | D4: =+'Pricing Workbook'!B9 -> 0 | F4: Metal Roof Vents | G4: =+'Pricing Workbook'!J4 -> 2 | H4: Soffit per ln ft | I4: =+'Pricing Workbook'!J12 -> 0
A5: Additional squares | B5: =SUM('Pricing Workbook'!F5:F9) -> 0 | C5: Rake | D5: =+'Pricing Workbook'!B8 -> 0 | F5: Electrical Boot | G5: =+'Pricing Workbook'!J5 -> 0 | H5: Gutters per ln ft | I5: =+'Pricing Workbook'!J15 -> 0
A6: Labor Squares | B6: =SUM(B2:B5) -> 58 | C6: Valley | D6: =+'Pricing Workbook'!B7 -> 0 | F6: Decking (per sheet) | G6: =+'Pricing Workbook'!J6 -> 10 | H6: # of Downspouts | I6: =+'Pricing Workbook'!J16 -> 0
F7: Structural Framing ln ft | G7: =+'Pricing Workbook'!J7 -> 0 | H7: gutter guards per ln ft | I7: =+'Pricing Workbook'!J17 -> 0
A8: Margin | B8: =+'Pricing Workbook'!B19 -> 0.41 | F8: Wall Flashing ln ft | G8: =+'Pricing Workbook'!J8 -> 35 | H8: Smart Vents per ln ft | I8: =+'Pricing Workbook'!J13 -> 0
F9: Chimney Flashing | G9: =+'Pricing Workbook'!J9 -> 0
A11: Products
A12: Advantage | B12: Quantity | C12: Cost | E12: Advantage Plus | F12: Quantity | G12: Cost | I12: Poly Shingle | J12: Quantity | K12: Cost
A13: GAF HDZ Shingle | B13: =G70 -> 177 | C13: =I70 -> 7301.25 | E13: Atlas Pinnacle Shingle | F13: =G74 -> 177 | G13: =I70 -> 7301.25 | I13: Malarkey Vista Shingle | J13: =G78 -> 177 | K13: =I78 -> 9735
A14: GAF HDZ Ridge | B14: =G71 -> 0 | C14: =I71 -> 0 | E14: Atlas Ridge | F14: =G75 -> 0 | G14: =I75 -> 0 | I14: Malarkey Ridge | J14: =G79 -> 0 | K14: =I79 -> 0
A15: GAF starter | B15: =G72 -> 0 | C15: =I72 -> 0 | E15: Atlas starter | F15: =G76 -> 0 | G15: =I76 -> 0 | I15: Malarkey starter | J15: =G80 -> 0 | K15: =I80 -> 0
A16: Synthetic Underlayment | B16: =G108 -> 6 | C16: =I108 -> 442.2 | E16: Synthetic Underlayment | F16: =G108 -> 6 | G16: =I108 -> 442.2 | I16: Synthetic Underlayment | J16: =G108 -> 6 | K16: =I108 -> 442.2
A17: Ice and Water Shield | B17: =G109 -> 0 | C17: =I109 -> 0 | E17: Ice and Water Shield | F17: =G109 -> 0 | G17: =I109 -> 0 | I17: Ice and Water Shield | J17: =G109 -> 0 | K17: =I109 -> 0
A18: Drip Edge | B18: =G83 -> 0 | C18: =I83 -> 0 | E18: Drip Edge | F18: =G83 -> 0 | G18: =I83 -> 0 | I18: Drip Edge | J18: =G83 -> 0 | K18: =I83 -> 0
A19: Ridge Vent | B19: =G84 -> 0 | C19: =I84 -> 0 | E19: Ridge Vent | F19: =G84 -> 0 | G19: =I84 -> 0 | I19: Ridge Vent | J19: =G84 -> 0 | K19: =I84 -> 0
A20: Cap Nails | B20: =G110 -> 2 | C20: =I110 -> 63.8 | E20: Cap Nails | F20: =G110 -> 2 | G20: =I110 -> 63.8 | I20: Cap Nails | J20: =G110 -> 2 | K20: =I110 -> 63.8
A21: Coil Nails | B21: =G82 -> 3 | C21: =I82 -> 151.8 | E21: Coil Nails | F21: =G82 -> 3 | G21: =I82 -> 151.8 | I21: Coil Nails | J21: =G82 -> 3 | K21: =I82 -> 151.8
A22: Spray Paint | B22: =G111 -> 1 | C22: =I111 -> 11 | E22: Spray Paint | F22: =G111 -> 1 | G22: =I111 -> 11 | I22: Spray Paint | J22: =G111 -> 1 | K22: =I111 -> 11
A23: Geocel | B23: =G112 -> 2 | C23: =I112 -> 33 | E23: Geocel | F23: =G112 -> 2 | G23: =I112 -> 33 | I23: Geocel | J23: =G112 -> 2 | K23: =I112 -> 33
A24: Shingle Delivery | B24: =G86 -> 1 | C24: =I86 -> 275 | E24: Shingle Delivery | F24: =G86 -> 1 | G24: =I86 -> 275 | I24: Poly Shingle Delivery | J24: =G87 -> 1 | K24: =I87 -> 825
A25: Project Manager | B25: =G152 -> 1 | C25: =I152 -> 500 | E25: Project Manager | F25: =G152 -> 1 | G25: =I152 -> 500 | I25: Project Manager | J25: =G152 -> 1 | K25: =I152 -> 500
A26: Shingle Labor | B26: =G135 -> 58 | C26: =I135 -> 4640 | E26: Shingle Labor | F26: =G135 -> 58 | G26: =I135 -> 4640 | I26: Shingle Labor | J26: =G135 -> 58 | K26: =I135 -> 4640
A27: non-walkable | B27: =G147 -> 0 | C27: =I147 -> 0 | E27: non-walkable | F27: =G147 -> 0 | G27: =I147 -> 0 | I27: non-walkable | J27: =G147 -> 0 | K27: =I147 -> 0
A28: Flat roof | B28: =G148 -> 0 | C28: =I148 -> 0 | E28: Flat roof | F28: =G148 -> 0 | G28: =I148 -> 0 | I28: Flat roof | J28: =G148 -> 0 | K28: =I148 -> 0
A29: Dump fee | B29: =G138 -> 3 | C29: =I138 -> 750 | E29: Dump fee | F29: =G138 -> 3 | G29: =I138 -> 750 | I29: Dump Fee | J29: =G138 -> 3 | K29: =I138 -> 750
A30: Free 3 sheets | B30: =G153 -> 1 | C30: =I153 -> 220 | E30: Free 3 sheets | F30: =G153 -> 1 | G30: =I153 -> 220 | I30: Free 3 Sheets | J30: =G153 -> 1 | K30: =I153 -> 220
A31: Full Report Fee | B31: =G154 -> 1 | C31: =I154 -> 55 | E31: Full Report Fee | F31: =G154 -> 1 | G31: =I154 -> 55 | I31: Full Report Fee | J31: =G154 -> 1 | K31: =I154 -> 55
B32: Total | C32: =SUM(C13:C31) -> 14443.05 | F32: Total | G32: =SUM(G13:G31) -> 14443.05 | J32: Total | K32: =SUM(K13:K31) -> 17426.8
A34: Classic Rib Panel | B34: Quantity | C34: Cost | E34: Lifetime Pro | F34: Quantity | G34: Cost | I34: Lifetime Ultra | J34: Quantity | K34: Cost
A35: Rib Panel 29g | B35: =G91 -> 58 | C35: =I91 -> 11165 | E35: Rib Panel 26g | F35: =G92 -> 58 | G35: =I92 -> 15950 | I35: Standing seam | J35: =G93 -> 58 | K35: =I93 -> 14355
A36: 29g Ridge | B36: =G95 -> 0 | C36: =I95 -> 0 | E36: 29g Ridge | F36: =G95 -> 0 | G36: =I95 -> 0 | I36: 29g Ridge | J36: =G95 -> 0 | K36: =I95 -> 0
A37: 29g Hip | B37: =G96 -> 0 | C37: =I96 -> 0 | E37: 29g Hip | F37: =G96 -> 0 | G37: =I96 -> 0 | I37: 29g Hip | J37: =G96 -> 0 | K37: =I96 -> 0
A38: 29g eave | B38: =G97 -> 0 | C38: =I97 -> 0 | E38: 29g eave | F38: =G97 -> 0 | G38: =I97 -> 0 | I38: 29g eave | J38: =G97 -> 0 | K38: =I97 -> 0
A39: 29g rake | B39: =G98 -> 0 | C39: =I98 -> 0 | E39: 29g rake | F39: =G98 -> 0 | G39: =I98 -> 0 | I39: 29g rake | J39: =G98 -> 0 | K39: =I98 -> 0
A40: 29g valley | B40: =G99 -> 0 | C40: =I99 -> 0 | E40: 29g valley | F40: =G99 -> 0 | G40: =I99 -> 0 | I40: 29g valley | J40: =G99 -> 0 | K40: =I99 -> 0
A41: Colored Screws | B41: =G101 -> 20 | C41: =I101 -> 365.2 | E41: Colored Screws | F41: =G101 -> 20 | G41: =I101 -> 365.2 | I41: Colored Screws | J41: =G101 -> 20 | K41: =I101 -> 365.2
A42: Butyl Tape | B42: =G102 -> 8 | C42: =I102 -> 61.6 | E42: Butyl Tape | F42: =G102 -> 8 | G42: =I102 -> 61.6 | I42: Butyl Tape | J42: =G102 -> 8 | K42: =I102 -> 61.6
...
